<?xml version="1.0.0"?>
<robot name ="my_robot">
    <material name="green">
        <color rgba="0 0.6 0 1"/>
    </material>
    <material name="grey">
        <color rgba="0.7 0.7 0.7 1" />
    </material>
    <link name="base_link">
        <visual>
            <geometry>
                <box size="0.6 0.4 0.2" />
            </geometry>
            <origin xyz="0 0 0" rpy="0 0 0" />
            <material name="green" />
        </visual>
    </link>
    <link name="another_link">
        <visual>
            <geometry>
                <cylinder radius="0.1" length="0.3"/>
            </geometry>
            <origin xyz="0 0 0.15" rpy="0 0 0" />  
            <material name="grey" />
        </visual>
    </link>
    <joint name="base_another_join" type = "revolute">
        <parent link = "base_link" />    
        <child link = "another_link" />
        <origin xyz="0 0 0.2" rpy = "0 0 0" />
        <axis xyz="0 0 1" />
    </joint>
</robot>